Workbook

Sheet subscriptions
A1: subscription_id | B1: customer_id | C1: plan_tier | D1: start_date | E1: end_date | F1: billing_cycle | G1: mrr_amount | H1: status | I1: change_type
A2: SUB000001 | B2: CUST00001 | C2: Starter | D2: 45851 | F2: Monthly | G2: 46.55 | H2: Active | I2: New
A3: SUB000002 | B3: CUST00002 | C3: Starter | D3: 45924 | F3: Monthly | G3: 46.55 | H3: Active | I3: New
A4: SUB000003 | B4: CUST00002 | C4: Growth | D4: 46015 | F4: Monthly | G4: 189.05 | H4: Active | I4: Upgrade
A5: SUB000004 | B5: CUST00003 | C5: Enterprise | D5: 45906 | F5: Annual | G5: 899 | H5: Active | I5: New
A6: SUB000005 | B6: CUST00004 | C6: Starter | D6: 45721 | E6: 45935 | F6: Monthly | G6: 46.55 | H6: Cancelled | I6: New
A7: SUB000006 | B7: CUST00005 | C7: Growth | D7: 45535 | F7: Monthly | G7: 199 | H7: Active | I7: New
A8: SUB000007 | B8: CUST00006 | C8: Growth | D8: 45714 | F8: Monthly | G8: 189.05 | H8: Active | I8: New
A9: SUB000008 | B9: CUST00007 | C9: Enterprise | D9: 45234 | F9: Annual | G9: 809.1 | H9: Active | I9: New
A10: SUB000009 | B10: CUST00008 | C10: Starter | D10: 45296 | F10: Annual | G10: 49 | H10: Active | I10: New
A11: SUB000010 | B11: CUST00009 | C11: Starter | D11: 45157 | F11: Annual | G11: 44.1 | H11: Active | I11: New
A12: SUB000011 | B12: CUST00010 | C12: Enterprise | D12: 45718 | F12: Monthly | G12: 899 | H12: Active | I12: New
A13: SUB000012 | B13: CUST00011 | C13: Enterprise | D13: 45962 | F13: Monthly | G13: 899 | H13: Active | I13: New
A14: SUB000013 | B14: CUST00012 | C14: Enterprise | D14: 45434 | F14: Monthly | G14: 899 | H14: Active | I14: New
A15: SUB000014 | B15: CUST00013 | C15: Starter | D15: 45904 | E15: 45965 | F15: Monthly | G15: 46.55 | H15: Cancelled | I15: New
A16: SUB000015 | B16: CUST00014 | C16: Starter | D16: 45890 | E16: 45951 | F16: Monthly | G16: 49 | H16: Cancelled | I16: New
A17: SUB000016 | B17: CUST00015 | C17: Growth | D17: 45027 | E17: 45210 | F17: Monthly | G17: 179.1 | H17: Cancelled | I17: New
A18: SUB000017 | B18: CUST00016 | C18: Enterprise | D18: 45253 | F18: Monthly | G18: 899 | H18: Active | I18: New
A19: SUB000018 | B19: CUST00017 | C19: Enterprise | D19: 45571 | F19: Monthly | G19: 899 | H19: Active | I19: New
A20: SUB000019 | B20: CUST00018 | C20: Growth | D20: 45794 | F20: Monthly | G20: 199 | H20: Active | I20: New
A21: SUB000020 | B21: CUST00019 | C21: Growth | D21: 45867 | E21: 45959 | F21: Monthly | G21: 179.1 | H21: Cancelled | I21: New
A22: SUB000021 | B22: CUST00020 | C22: Starter | D22: 45650 | F22: Annual | G22: 44.1 | H22: Active | I22: New
A23: SUB000022 | B23: CUST00020 | C23: Growth | D23: 45893 | F23: Annual | G23: 179.1 | H23: Active | I23: Upgrade
A24: SUB000023 | B24: CUST00021 | C24: Starter | D24: 45556 | E24: 45709 | F24: Monthly | G24: 44.1 | H24: Cancelled | I24: New
A25: SUB000024 | B25: CUST00022 | C25: Starter | D25: 45864 | F25: Monthly | G25: 49 | H25: Active | I25: New
A26: SUB000025 | B26: CUST00023 | C26: Growth | D26: 45957 | F26: Annual | G26: 179.1 | H26: Active | I26: New
A27: SUB000026 | B27: CUST00024 | C27: Enterprise | D27: 45423 | F27: Monthly | G27: 809.1 | H27: Active | I27: New
A28: SUB000027 | B28: CUST00025 | C28: Enterprise | D28: 45559 | F28: Monthly | G28: 809.1 | H28: Active | I28: New
A29: SUB000028 | B29: CUST00026 | C29: Growth | D29: 45921 | E29: 45951 | F29: Monthly | G29: 199 | H29: Cancelled | I29: New
A30: SUB000029 | B30: CUST00027 | C30: Starter | D30: 45333 | F30: Monthly | G30: 46.55 | H30: Active | I30: New
A31: SUB000030 | B31: CUST00028 | C31: Starter | D31: 45834 | F31: Annual | G31: 49 | H31: Active | I31: New
A32: SUB000031 | B32: CUST00029 | C32: Enterprise | D32: 45702 | F32: Monthly | G32: 899 | H32: Active | I32: New
A33: SUB000032 | B33: CUST00030 | C33: Growth | D33: 45706 | F33: Annual | G33: 199 | H33: Active | I33: New
A34: SUB000033 | B34: CUST00031 | C34: Enterprise | D34: 45369 | E34: 45522 | F34: Annual | G34: 764.15 | H34: Cancelled | I34: New
A35: SUB000034 | B35: CUST00032 | C35: Starter | D35: 45868 | E35: 45960 | F35: Monthly | G35: 46.55 | H35: Cancelled | I35: New
A36: SUB000035 | B36: CUST00033 | C36: Starter | D36: 45792 | E36: 45853 | F36: Annual | G36: 49 | H36: Cancelled | I36: New
A37: SUB000036 | B37: CUST00034 | C37: Growth | D37: 45423 | F37: Monthly | G37: 199 | H37: Active | I37: New
A38: SUB000037 | B38: CUST00035 | C38: Growth | D38: 45712 | F38: Monthly | G38: 179.1 | H38: Active | I38: New
A39: SUB000038 | B39: CUST00036 | C39: Starter | D39: 45618 | F39: Monthly | G39: 49 | H39: Active | I39: New
A40: SUB000039 | B40: CUST00036 | C40: Growth | D40: 45952 | F40: Annual | G40: 199 | H40: Active | I40: Upgrade
...

Sheet invoices
A1: invoice_id | B1: subscription_id | C1: invoice_date | D1: amount_due | E1: amount_paid | F1: payment_status | G1: discount_pct
A2: INV0000001 | B2: SUB000001 | C2: 45851 | D2: 46.55 | E2: 46.55 | F2: Paid | G2: 5
A3: INV0000002 | B3: SUB000001 | C3: 45882 | D3: 46.55 | E3: 46.55 | F3: Paid | G3: 5
A4: INV0000003 | B4: SUB000001 | C4: 45913 | D4: 46.55 | E4: 46.55 | F4: Paid | G4: 5
A5: INV0000004 | B5: SUB000001 | C5: 45943 | D5: 46.55 | E5: 46.55 | F5: Paid | G5: 5
A6: INV0000005 | B6: SUB000001 | C6: 45974 | D6: 46.55 | E6: 46.55 | F6: Paid | G6: 5
A7: INV0000006 | B7: SUB000001 | C7: 46004 | D7: 46.55 | E7: 46.55 | F7: Paid | G7: 5
A8: INV0000007 | B8: SUB000002 | C8: 45924 | D8: 46.55 | E8: 46.55 | F8: Paid | G8: 5
A9: INV0000008 | B9: SUB000002 | C9: 45954 | D9: 46.55 | E9: 0 | F9: Failed | G9: 5
A10: INV0000009 | B10: SUB000002 | C10: 45985 | D10: 46.55 | E10: 46.55 | F10: Paid | G10: 5
A11: INV0000010 | B11: SUB000002 | C11: 46015 | D11: 46.55 | E11: 46.55 | F11: Paid | G11: 5
A12: INV0000011 | B12: SUB000003 | C12: 46015 | D12: 189.05 | E12: 189.05 | F12: Paid | G12: 5
A13: INV0000012 | B13: SUB000004 | C13: 45906 | D13: 899 | E13: 899 | F13: Paid | G13: 0
... A36128: INV0036127 | B36128: SUB003387 | C36128: 45994 | D36128: 169.15 | E36128: 169.15 | F36128: Paid | G36128: 15

Sheet Nov_2025_Invoice_Extract
A1: Northbeam Analytics — Finance Reconciliation
A2: Source: invoices.csv joined with subscriptions.csv for plan_tier — November 2025
A4: invoice_date | B4: subscription_id | C4: plan_tier | D4: invoice_id | E4: amount_due | F4: amount_paid | G4: payment_status | H4: discount_pct
A5: 45974 | B5: SUB000001 | C5: =_xlfn.XLOOKUP(B6, subscriptions!A:A, subscriptions!C:C) -> Starter | D5: =_xlfn.XLOOKUP($B5,invoices!$B:$B,invoices!$A:$A,"") -> INV0000001 | E5: =_xlfn.XLOOKUP($B5,invoices!$B:$B,invoices!$D:$D,"") -> 46.55 | F5: =_xlfn.XLOOKUP($B5,invoices!$B:$B,invoices!$E:$E,"") -> 46.55 | G5: =_xlfn.XLOOKUP($B5,invoices!$B:$B,invoices!$F:$F,"") -> Paid | H5: =_xlfn.XLOOKUP($B5,invoices!$B:$B,invoices!$G:$G,"") -> 5
A6: 45985 | B6: SUB000002 | C6: =_xlfn.XLOOKUP(B7, subscriptions!A:A, subscriptions!C:C) -> Enterprise | D6: =_xlfn.XLOOKUP($B6,invoices!$B:$B,invoices!$A:$A,"") -> INV0000007 | E6: =_xlfn.XLOOKUP($B6,invoices!$B:$B,invoices!$D:$D,"") -> 46.55 | F6: =_xlfn.XLOOKUP($B6,invoices!$B:$B,invoices!$E:$E,"") -> 46.55 | G6: =_xlfn.XLOOKUP($B6,invoices!$B:$B,invoices!$F:$F,"") -> Paid | H6: =_xlfn.XLOOKUP($B6,invoices!$B:$B,invoices!$G:$G,"") -> 5
A7: 45967 | B7: SUB000004 | C7: =_xlfn.XLOOKUP(B7, subscriptions!A:A, subscriptions!C:C) -> Enterprise | D7: =_xlfn.XLOOKUP($B7,invoices!$B:$B,invoices!$A:$A,"") -> INV0000012 | E7: =_xlfn.XLOOKUP($B7,invoices!$B:$B,invoices!$D:$D,"") -> 899 | F7: =_xlfn.XLOOKUP($B7,invoices!$B:$B,invoices!$E:$E,"") -> 899 | G7: =_xlfn.XLOOKUP($B7,invoices!$B:$B,invoices!$F:$F,"") -> Paid | H7: =_xlfn.XLOOKUP($B7,invoices!$B:$B,invoices!$G:$G,"") -> 0
A8: 45989 | B8: SUB000006 | C8: =_xlfn.XLOOKUP(B8, subscriptions!A:A, subscriptions!C:C) -> Growth | D8: =_xlfn.XLOOKUP($B8,invoices!$B:$B,invoices!$A:$A,"") -> INV0000024 | E8: =_xlfn.XLOOKUP($B8,invoices!$B:$B,invoices!$D:$D,"") -> 199 | F8: =_xlfn.XLOOKUP($B8,invoices!$B:$B,invoices!$E:$E,"") -> 0 | G8: =_xlfn.XLOOKUP($B8,invoices!$B:$B,invoices!$F:$F,"") -> Failed | H8: =_xlfn.XLOOKUP($B8,invoices!$B:$B,invoices!$G:$G,"") -> 0
A9: 45987 | B9: SUB000007 | C9: =_xlfn.XLOOKUP(B9, subscriptions!A:A, subscriptions!C:C) -> Growth | D9: =_xlfn.XLOOKUP($B9,invoices!$B:$B,invoices!$A:$A,"") -> INV0000041 | E9: =_xlfn.XLOOKUP($B9,invoices!$B:$B,invoices!$D:$D,"") -> 189.05 | F9: =_xlfn.XLOOKUP($B9,invoices!$B:$B,invoices!$E:$E,"") -> 189.05 | G9: =_xlfn.XLOOKUP($B9,invoices!$B:$B,invoices!$F:$F,"") -> Paid | H9: =_xlfn.XLOOKUP($B9,invoices!$B:$B,invoices!$G:$G,"") -> 5
A10: 45965 | B10: SUB000008 | C10: =_xlfn.XLOOKUP(B10, subscriptions!A:A, subscriptions!C:C) -> Enterprise | D10: =_xlfn.XLOOKUP($B10,invoices!$B:$B,invoices!$A:$A,"") -> INV0000052 | E10: =_xlfn.XLOOKUP($B10,invoices!$B:$B,invoices!$D:$D,"") -> 809.1 | F10: =_xlfn.XLOOKUP($B10,invoices!$B:$B,invoices!$E:$E,"") -> 809.1 | G10: =_xlfn.XLOOKUP($B10,invoices!$B:$B,invoices!$F:$F,"") -> Paid | H10: =_xlfn.XLOOKUP($B10,invoices!$B:$B,invoices!$G:$G,"") -> 10
A11: 45966 | B11: SUB000009 | C11: =_xlfn.XLOOKUP(B11, subscriptions!A:A, subscriptions!C:C) -> Starter | D11: =_xlfn.XLOOKUP($B11,invoices!$B:$B,invoices!$A:$A,"") -> INV0000078 | E11: =_xlfn.XLOOKUP($B11,invoices!$B:$B,invoices!$D:$D,"") -> 49 | F11: =_xlfn.XLOOKUP($B11,invoices!$B:$B,invoices!$E:$E,"") -> 49 | G11: =_xlfn.XLOOKUP($B11,invoices!$B:$B,invoices!$F:$F,"") -> Paid | H11: =_xlfn.XLOOKUP($B11,invoices!$B:$B,invoices!$G:$G,"") -> 0
A12: 45980 | B12: SUB000010 | C12: =_xlfn.XLOOKUP(B12, subscriptions!A:A, subscriptions!C:C) -> Starter | D12: =_xlfn.XLOOKUP($B12,invoices!$B:$B,invoices!$A:$A,"") -> INV0000102 | E12: =_xlfn.XLOOKUP($B12,invoices!$B:$B,invoices!$D:$D,"") -> 44.1 | F12: =_xlfn.XLOOKUP($B12,invoices!$B:$B,invoices!$E:$E,"") -> 44.1 | G12: =_xlfn.XLOOKUP($B12,invoices!$B:$B,invoices!$F:$F,"") -> Paid | H12: =_xlfn.XLOOKUP($B12,invoices!$B:$B,invoices!$G:$G,"") -> 10
A13: 45963 | B13: SUB000011 | C13: =_xlfn.XLOOKUP(B13, subscriptions!A:A, subscriptions!C:C) -> Enterprise | D13: =_xlfn.XLOOKUP($B13,invoices!$B:$B,invoices!$A:$A,"") -> INV0000131 | E13: =_xlfn.XLOOKUP($B13,invoices!$B:$B,invoices!$D:$D,"") -> 899 | F13: =_xlfn.XLOOKUP($B13,invoices!$B:$B,invoices!$E:$E,"") -> 899 | G13: =_xlfn.XLOOKUP($B13,invoices!$B:$B,invoices!$F:$F,"") -> Paid | H13: =_xlfn.XLOOKUP($B13,invoices!$B:$B,invoices!$G:$G,"") -> 0
A14: 45962 | B14: SUB000012 | C14: =_xlfn.XLOOKUP(B14, subscriptions!A:A, subscriptions!C:C) -> Enterprise | D14: =_xlfn.XLOOKUP($B14,invoices!$B:$B,invoices!$A:$A,"") -> INV0000141 | E14: =_xlfn.XLOOKUP($B14,invoices!$B:$B,invoices!$D:$D,"") -> 899 | F14: =_xlfn.XLOOKUP($B14,invoices!$B:$B,invoices!$E:$E,"") -> 899 | G14: =_xlfn.XLOOKUP($B14,invoices!$B:$B,invoices!$F:$F,"") -> Paid | H14: =_xlfn.XLOOKUP($B14,invoices!$B:$B,invoices!$G:$G,"") -> 0
A15: 45983 | B15: SUB000013 | C15: =_xlfn.XLOOKUP(B15, subscriptions!A:A, subscriptions!C:C) -> Enterprise | D15: =_xlfn.XLOOKUP($B15,invoices!$B:$B,invoices!$A:$A,"") -> INV0000143 | E15: =_xlfn.XLOOKUP($B15,invoices!$B:$B,invoices!$D:$D,"") -> 899 | F15: =_xlfn.XLOOKUP($B15,invoices!$B:$B,invoices!$E:$E,"") -> 899 | G15: =_xlfn.XLOOKUP($B15,invoices!$B:$B,invoices!$F:$F,"") -> Paid | H15: =_xlfn.XLOOKUP($B15,invoices!$B:$B,invoices!$G:$G,"") -> 0
A16: 45965 | B16: SUB000014 | C16: =_xlfn.XLOOKUP(B16, subscriptions!A:A, subscriptions!C:C) -> Starter | D16: =_xlfn.XLOOKUP($B16,invoices!$B:$B,invoices!$A:$A,"") -> INV0000163 | E16: =_xlfn.XLOOKUP($B16,invoices!$B:$B,invoices!$D:$D,"") -> 46.55 | F16: =_xlfn.XLOOKUP($B16,invoices!$B:$B,invoices!$E:$E,"") -> 46.55 | G16: =_xlfn.XLOOKUP($B16,invoices!$B:$B,invoices!$F:$F,"") -> Paid | H16: =_xlfn.XLOOKUP($B16,invoices!$B:$B,invoices!$G:$G,"") -> 5
A17: 45984 | B17: SUB000017 | C17: =_xlfn.XLOOKUP(B17, subscriptions!A:A, subscriptions!C:C) -> Enterprise | D17: =_xlfn.XLOOKUP($B17,invoices!$B:$B,invoices!$A:$A,"") -> INV0000176 | E17: =_xlfn.XLOOKUP($B17,invoices!$B:$B,invoices!$D:$D,"") -> 899 | F17: =_xlfn.XLOOKUP($B17,invoices!$B:$B,invoices!$E:$E,"") -> 899 | G17: =_xlfn.XLOOKUP($B17,invoices!$B:$B,invoices!$F:$F,"") -> Paid | H17: =_xlfn.XLOOKUP($B17,invoices!$B:$B,invoices!$G:$G,"") -> 0
A18: 45967 | B18: SUB000018 | C18: =_xlfn.XLOOKUP(B18, subscriptions!A:A, subscriptions!C:C) -> Enterprise | D18: =_xlfn.XLOOKUP($B18,invoices!$B:$B,invoices!$A:$A,"") -> INV0000202 | E18: =_xlfn.XLOOKUP($B18,invoices!$B:$B,invoices!$D:$D,"") -> 899 | F18: =_xlfn.XLOOKUP($B18,invoices!$B:$B,invoices!$E:$E,"") -> 899 | G18: =_xlfn.XLOOKUP($B18,invoices!$B:$B,invoices!$F:$F,"") -> Paid | H18: =_xlfn.XLOOKUP($B18,invoices!$B:$B,invoices!$G:$G,"") -> 0
... A2894: 45964 | B2894: SUB003387 | C2894: =_xlfn.XLOOKUP(B2894, subscriptions!A:A, subscriptions!C:C) -> Growth | D2894: =_xlfn.XLOOKUP($B2894,invoices!$B:$B,invoices!$A:$A,"") -> INV0036123 | E2894: =_xlfn.XLOOKUP($B2894,invoices!$B:$B,invoices!$D:$D,"") -> 169.15 | F2894: =_xlfn.XLOOKUP($B2894,invoices!$B:$B,invoices!$E:$E,"") -> 169.15 | G2894: =_xlfn.XLOOKUP($B2894,invoices!$B:$B,invoices!$F:$F,"") -> Paid | H2894: =_xlfn.XLOOKUP($B2894,invoices!$B:$B,invoices!$G:$G,"") -> 15

Sheet Reconciliation_Summary
A1: November 2025 Revenue Reconciliation
A4: Headline Reconciliation
A5: Total Invoices Issued | B5: =COUNTA(Nov_2025_Invoice_Extract!A5:A2894) -> 2890
A6: Total Amount Due ($) | B6: =SUM(Nov_2025_Invoice_Extract!E5:E2894) -> 826873.3
A7: Total Amount Paid ($) | B7: =SUM(Nov_2025_Invoice_Extract!F5:F2894) -> 752617.95
A8: Total Revenue Gap ($) | B8: =B6-B7 -> 74255.35
A9: Revenue Collection Rate (%) | B9: =B7/B6 -> 0.91019743
A12: Breakdown by payment_status
A13: Payment Status | B13: Invoice Count | C13: Amount Due ($) | D13: Amount Paid ($) | E13: % of Total Due
A14: Paid | B14: =COUNTIF(Nov_2025_Invoice_Extract!G5:G2894, A14) -> 2611 | C14: =SUMIF(Nov_2025_Invoice_Extract!G5:G2894, A14, Nov_2025_Invoice_Extract!E5:E2894) -> 752617.95 | D14: =SUMIF(Nov_2025_Invoice_Extract!G5:G2894, A14, Nov_2025_Invoice_Extract!F5:F2894) -> 752617.95 | E14: =C14/$B$6 -> 0.91019743
A15: Failed | B15: =COUNTIF(Nov_2025_Invoice_Extract!G6:G2895, A15) -> 222 | C15: =SUMIF(Nov_2025_Invoice_Extract!G6:G2895, A15, Nov_2025_Invoice_Extract!E6:E2895) -> 55334.35 | D15: =SUMIF(Nov_2025_Invoice_Extract!G6:G2895, A15, Nov_2025_Invoice_Extract!F6:F2895) -> 0 | E15: =C15/$B$6 -> 0.066919986
A16: Refunded | B16: =COUNTIF(Nov_2025_Invoice_Extract!G7:G2896, A16) -> 57 | C16: =SUMIF(Nov_2025_Invoice_Extract!G7:G2896, A16, Nov_2025_Invoice_Extract!E7:E2896) -> 18921 | D16: =SUMIF(Nov_2025_Invoice_Extract!G7:G2896, A16, Nov_2025_Invoice_Extract!F7:F2896) -> 0 | E16: =C16/$B$6 -> 0.022882587
A17: Total | B17: =SUM(B14:B16) -> 2890 | C17: =SUM(C14:C16) -> 826873.3 | D17: =SUM(D14:D16) -> 752617.95 | E17: =SUM(E14:E16) -> 1
A19: Breakdown by Plan Tier
A20: Plan Tier | B20: Invoice Count | C20: Amount Due ($) | D20: Amount Paid ($) | E20: Collection Rate (%)
A21: Starter | B21: =COUNTIF(Nov_2025_Invoice_Extract!C5:C2894, A21) -> 1040 | C21: =SUMIF(Nov_2025_Invoice_Extract!C5:C2894, A21, Nov_2025_Invoice_Extract!E5:E2894) -> 47659.85 | D21: =SUMIF(Nov_2025_Invoice_Extract!C5:C2894, A21, Nov_2025_Invoice_Extract!F5:F2894) -> 42870.1 | E21: =D21/C21 -> 0.89950136
A22: Growth | B22: =COUNTIF(Nov_2025_Invoice_Extract!C6:C2895, A22) -> 1186 | C22: =SUMIF(Nov_2025_Invoice_Extract!C6:C2895, A22, Nov_2025_Invoice_Extract!E6:E2895) -> 221427.3 | D22: =SUMIF(Nov_2025_Invoice_Extract!C6:C2895, A22, Nov_2025_Invoice_Extract!F6:F2895) -> 199159.2 | E22: =D22/C22 -> 0.89943381
A23: Enterprise | B23: =COUNTIF(Nov_2025_Invoice_Extract!C7:C2896, A23) -> 663 | C23: =SUMIF(Nov_2025_Invoice_Extract!C7:C2896, A23, Nov_2025_Invoice_Extract!E7:E2896) -> 557739.6 | D23: =SUMIF(Nov_2025_Invoice_Extract!C7:C2896, A23, Nov_2025_Invoice_Extract!F7:F2896) -> 510542.1 | E23: =D23/C23 -> 0.91537718
